#VRML_SIM R2021a utf8
WorldInfo {
  coordinateSystem "NUE"
}
Viewpoint {
  orientation 0.4629546968181018 0.7775440609995924 0.42555632047746816 4.531556449761923
  position -0.28643945289491807 0.5109017322780353 0.22318062207926903
}
TexturedBackground {
}
TexturedBackgroundLight {
}
RectangleArena {
  floorTileSize 0.25 0.25
  wallHeight 0.05
}
WoodenBox {
  translation 0.205843 0.05 -0.221732
  size 0.1 0.1 0.1
}
WoodenBox {
  translation -0.1926 0.05 -0.265934
  name "wooden box(2)"
  size 0.1 0.1 0.1
}
WoodenBox {
  translation 0.12104 0.05 0.28743
  name "wooden box(1)"
  size 0.1 0.1 0.1
}
WoodenBox {
  translation -0.0855932 0.05 0.447467
  name "wooden box(3)"
  size 0.1 0.1 0.1
}
Robot {
  translation 0 0.04 0
  children [
    DEF Camera Robot {
      children [
        Camera {
          translation 0 0.03 0.09
          rotation 0 1 0 3.14
          children [
            DEF cameraShape Shape {
              appearance PBRAppearance {
              }
              geometry Box {
                size 0.01 0.01 0.01
              }
            }
          ]
          boundingObject USE cameraShape
          physics Physics {
          }
        }
      ]
      name "robot(1)"
      boundingObject USE cameraShape
      physics Physics {
      }
      controller "CameraComponent"
      supervisor TRUE
    }
    DEF Distance_Sensor Robot {
      children [
        DEF ds_center DistanceSensor {
          translation 0 0 0.101
          rotation 0 1 0 -1.5707853071795865
          children [
            DEF SENSOR Shape {
              appearance PBRAppearance {
                baseColor 0.203922 0.396078 0.643137
                roughness 1
                metalness 0
              }
              geometry Box {
                size 0.01 0.01 0.01
              }
            }
          ]
          name "ds_center"
          boundingObject USE SENSOR
          physics Physics {
          }
        }
      ]
      boundingObject USE SENSOR
      physics Physics {
      }
      controller "DistanceSensor"
      supervisor TRUE
    }
    HingeJoint {
      jointParameters HingeJointParameters {
        anchor -0.06 0 -0.05
      }
      device [
        RotationalMotor {
          name "wheel4"
        }
      ]
      endPoint DEF WHEEL4 Solid {
        translation -0.06 0 -0.05
        rotation 0 0 1 1.5708
        children [
          DEF WHEEL Shape {
            appearance PBRAppearance {
            }
            geometry Cylinder {
              height 0.02
              radius 0.04
            }
          }
        ]
        name "solid3"
        boundingObject USE WHEEL
        physics Physics {
        }
      }
    }
    HingeJoint {
      jointParameters HingeJointParameters {
        anchor 0.06 0 -0.05
      }
      device [
        RotationalMotor {
          name "wheel3"
        }
      ]
      endPoint DEF WHEEL3 Solid {
        translation 0.06 0 -0.05
        rotation 0 0 1 1.5708
        children [
          DEF WHEEL Shape {
            appearance PBRAppearance {
            }
            geometry Cylinder {
              height 0.02
              radius 0.04
            }
          }
        ]
        name "solid2"
        boundingObject USE WHEEL
        physics Physics {
        }
      }
    }
    HingeJoint {
      jointParameters HingeJointParameters {
        anchor -0.06 0 0.05
      }
      device [
        RotationalMotor {
          name "wheel2"
        }
      ]
      endPoint DEF WHEEL2 Solid {
        translation -0.06 0 0.05
        rotation 0 0 1 1.57079
        children [
          DEF WHEEL Shape {
            appearance PBRAppearance {
            }
            geometry Cylinder {
              height 0.02
              radius 0.04
            }
          }
        ]
        name "solid1"
        boundingObject USE WHEEL
        physics Physics {
        }
      }
    }
    HingeJoint {
      jointParameters HingeJointParameters {
        anchor 0.06 0 0.05
      }
      device [
        RotationalMotor {
          name "wheel1"
        }
      ]
      endPoint DEF WHEEL1 Solid {
        translation 0.06 0 0.05
        rotation 0 0 1 1.5708
        children [
          DEF WHEEL Shape {
            appearance PBRAppearance {
            }
            geometry Cylinder {
              height 0.02
              radius 0.04
            }
          }
        ]
        boundingObject USE WHEEL
        physics DEF WHEEL_PH Physics {
        }
      }
    }
    DEF BODY Shape {
      appearance PBRAppearance {
        baseColor 1 0 0
        metalness 0
      }
      geometry Box {
        size 0.1 0.05 0.2
      }
    }
  ]
  boundingObject USE BODY
  physics Physics {
  }
  controller "WebotsMovement"
  supervisor TRUE
}
